    1: import pytest
    2: 
    3: import pandas as pd
    4: from pandas import Series
    5: import pandas._testing as tm
    6: 
    7: 
    8: def test_take_validate_axis():
    9:     # GH#51022
   10:     ser = Series([-1, 5, 6, 2, 4])
   11: 
   12:     msg = "No axis named foo for object type Series"
   13:     with pytest.raises(ValueError, match=msg):
   14:         ser.take([1, 2], axis="foo")
   15: 
   16: 
   17: def test_take():
   18:     ser = Series([-1, 5, 6, 2, 4])
   19: 
   20:     actual = ser.take([1, 3, 4])
   21:     expected = Series([5, 2, 4], index=[1, 3, 4])
   22:     tm.assert_series_equal(actual, expected)
   23: 
   24:     actual = ser.take([-1, 3, 4])
   25:     expected = Series([4, 2, 4], index=[4, 3, 4])
   26:     tm.assert_series_equal(actual, expected)
   27: 
   28:     msg = "indices are out-of-bounds"
   29:     with pytest.raises(IndexError, match=msg):
   30:         ser.take([1, 10])
   31:     with pytest.raises(IndexError, match=msg):
   32:         ser.take([2, 5])
   33: 
   34: 
   35: def test_take_categorical():
   36:     # https://github.com/pandas-dev/pandas/issues/20664
   37:     ser = Series(pd.Categorical(["a", "b", "c"]))
   38:     result = ser.take([-2, -2, 0])
   39:     expected = Series(
   40:         pd.Categorical(["b", "b", "a"], categories=["a", "b", "c"]), index=[1, 1, 0]
   41:     )
   42:     tm.assert_series_equal(result, expected)
   43: 
   44: 
   45: def test_take_slice_raises():
   46:     ser = Series([-1, 5, 6, 2, 4])
   47: 
   48:     msg = "Series.take requires a sequence of integers, not slice"
   49:     with pytest.raises(TypeError, match=msg):
   50:         ser.take(slice(0, 3, 1))
